Workbook
Name INTEXON: #REF!
Name RUBROS: '[1]B.D.'!$A$3:$C$8

Sheet Cuadro
B1: POSICIÓN DE CAJA ENE - JUNIO 2026
C2: Q1 (ENE-MAR) | D2: ABR | E2: MAY | F2: JUN | G2: ENE-JUNIO TOTAL
A3: x | B3: SALDO INICIAL DEL PERIODO | C3: =+'Detalle S10_Junio 2026'!O5 -> 213970.45 | D3: =+C13 -> 1214667.4 | E3: =+D13 -> 11226.4 | F3: =+E13 -> 47528.47 | G3: =+C3 -> 213970.45
B4: ENTRADAS DE CAJA
A5: a | B5: COBROS A CLIENTES / FACTURAS | C5: =+'Detalle S10_Junio 2026'!O86 -> 5560371.2 | D5: =+'Detalle S10_Junio 2026'!O676 -> 147028 | E5: =+'Detalle S10_Junio 2026'!O814 -> 449918.21 | F5: =+'Detalle S10_Junio 2026'!O990 -> 1249284.4 | G5: =SUM(C5:F5) -> 7406601.8
A6: b | B6: ANTICIPOS Y OTROS INGRESOS | C6: =+'Detalle S10_Junio 2026'!O96 -> 774938.87 | D6: =+'Detalle S10_Junio 2026'!O679 -> 213085.26 | E6: =+'Detalle S10_Junio 2026'!O822 -> 854089.05 | F6: =+'Detalle S10_Junio 2026'!O995 -> 233685.99 | G6: =SUM(C6:F6) -> 2075799.2
A7: a + b | B7: TOTAL ENTRADAS | C7: =SUM(C5:C6) -> 6335310 | D7: =SUM(D5:D6) -> 360113.26 | E7: =SUM(E5:E6) -> 1304007.3 | F7: =SUM(F5:F6) -> 1482970.4 | G7: =SUM(G5:G6) -> 9482400.9
B8: SALIDAS DE CAJA
A9: c | B9: REMUNERACIONES Y HONORARIOS (LOCADORES) | C9: =-+'Detalle S10_Junio 2026'!O139 -> 835295.83 | D9: =-+'Detalle S10_Junio 2026'!O695 -> 275321.89 | E9: =-+'Detalle S10_Junio 2026'!O841 -> 405879.14 | F9: =-'Detalle S10_Junio 2026'!O1075 -> 479140.47 | G9: =SUM(C9:F9) -> 1995637.3
A10: d | B10: PROVEEDORES, ARRIENDO, SERVICIOS Y OTROS | C10: =-+'Detalle S10_Junio 2026'!O631 -> 3124544.2 | D10: =-+'Detalle S10_Junio 2026'!O793 -> 820967.4 | E10: =-+'Detalle S10_Junio 2026'!O958 -> 693222.29 | F10: =-'Detalle S10_Junio 2026'!O1147 -> 767445.91 | G10: =SUM(C10:F10) -> 5406179.8
A11: e | B11: SUNAT / IMPUESTOS | C11: =-+'Detalle S10_Junio 2026'!O662 -> 1374773 | D11: =-+'Detalle S10_Junio 2026'!O803 -> 467265 | E11: =-+'Detalle S10_Junio 2026'!O968 -> 168603.76 | F11: =-'Detalle S10_Junio 2026'!O1167 -> 277542.16 | G11: =SUM(C11:F11) -> 2288183.9
A12: c + d + e | B12: TOTAL SALIDAS | C12: =SUM(C9:C11) -> 5334613.1 | D12: =SUM(D9:D11) -> 1563554.3 | E12: =SUM(E9:E11) -> 1267705.2 | F12: =SUM(F9:F11) -> 1524128.5 | G12: =SUM(G9:G11) -> 9690001.1
A13: z | B13: SALDO FINAL | C13: =+C3+C7-C12 -> 1214667.4 | D13: =+D3+D7-D12 -> 11226.4 | E13: =+E3+E7-E12 -> 47528.47 | F13: =+F3+F7-F12 -> 6370.3 | G13: =+G3+G7-G12 -> 6370.3
C17: SALIDAS | D17: ENTRADAS | E17: NETO
B18: CMO | C18: 2818347.4 | D18: 886628 | E18: -1931719.4
B19: AMERICANA | C19: 28000 | E19: -28000
B20: VC | C20: 566408 | E20: -566408
B21: ENGEREDE | C21: 8911 | E21: -8911
B22: ICYS | D22: 289100 | E22: 289100
B23: RY | C23: 215936 | D23: 955402 | E23: 739466
B24: OTROS ACREEDORES | C24: 1768576 | D24: -55630 | E24: -1824206
C25: 5406178.4 | D25: 2075500 | E25: -3330678.4
D26: 3330678.4

Sheet  cta 10
B2: INTEGRAL CONSULTORES
B3: Al 31 de Mayo de 2026
B5: CAJA Y BANCOS
C6: TC Compra | D6: 3.403
B7: DESCRIPCION | C7: US$ | D7: S/
B8: Total 10100021 Caja Chica MN | D8: 2000 | E8: no la tomamos para reporte
B9: Total 10410013 BBVA CONTINENTAL MN | D9: 1100.52
B10: Total 10410014 BBVA CONTINENTAL ME | C10: 1548.57 | D10: =+C10*D6 -> 5269.7837
B11: Total 10710021 BANCO NACIÓN - CTA DETRACCION | D11: 0
B12: SALDO AL 30 DE SETIEMBRE | D12: =SUM(D8:D11) -> 8370.3037 | E12: =+D11+D10+D9 -> 6370.3037 | F12: Importe S10
L60: =+L48+L56+L59+L51+L53 -> 0
M141: =14899454.51-M140 -> 14899455

Sheet Detalle S10_Junio 2026
A1: Item | B1: Cuenta Contable | C1: RUC Socio de Negocio | D1: Socio de Negocio | E1: Procedencia | F1: N° Asiento | G1: Libro | H1: Mes | I1: Periodo Contable | J1: Fecha de Transacción | K1: N° Documento | L1: N° Documento Pago | M1: MO | N1: Saldo Origen | O1: Saldo ( S/ ) | P1: Observación Documento | Q1: Observación | R1: Año | S1: F.Emisión
A2: o | B2: 10410013 BBVA CONTINENTAL MN | E2: 16. Asiento de Apertura | F2: 0000000001 | G2: Libro Diario | I2: 202600 Apertura 2026 | J2: 01/01/2026 | M2: S/ | N2: 121320.92 | O2: 121321.12 | P2: Asiento de Apertura | Q2: Asiento de Apertura | R2: 2026 | S2: 01/01/2026
A3: o | B3: 10710021 BANCO NACION - CTA DETRACCION | E3: 16. Asiento de Apertura | F3: 0000000001 | G3: Libro Diario | I3: 202600 Apertura 2026 | J3: 01/01/2026 | M3: S/ | N3: 91070 | O3: 91070 | P3: Asiento de Apertura | Q3: Asiento de Apertura | R3: 2026 | S3: 01/01/2026
A4: o | B4: 10410014 BBVA CONTINENTAL ME | E4: 16. Asiento de Apertura | F4: 0000000001 | G4: Libro Diario | I4: 202600 Apertura 2026 | J4: 01/01/2026 | M4: U$ | N4: 470.04 | O4: 1579.33 | P4: Asiento de Apertura | Q4: Asiento de Apertura | R4: 2026 | S4: 01/01/2026
A5: Total o | O5: =SUBTOTAL(9,O2:O4) -> 213970.45
A6: a | B6: 10410013 BBVA CONTINENTAL MN | C6: 20613390996 | D6: CONSORCIO HEALTH BERNALES | E6: 02. Transferencia a cuenta bancaria | F6: 0000001823 | G6: Caja y Bancos | H6: 46023 | I6: 202601 Enero 2026 | J6: 23/01/2026 | K6: FE E001-00000016 | L6: FE E001-00000016 | M6: S/ | N6: 320360.5 | O6: 320360.5 | P6: SERVICIO DE ASESORIA INTEGRAL EN LA ADMINISTRACION CONTRACTUAL PARA EL PROCESO: DISEÑO CONSTRUCCION Y EQUIPAMIENTO DEL NUEVO HOSPITAL NACIONAL SERGIO BERNALES, LOCALIDAD DE COLLIQUE, DISTRITO DE COMAS, PROVINCIA DE LIMA - ANTICIPO | Q6: COBRANZA DE FACTURA E001-16 | R6: 2026 | S6: 30/12/2024
A7: a | B7: 10410013 BBVA CONTINENTAL MN | C7: 20608830392 | D7: CONSORCIO STILER - RIPCONCIV - TECNOEDIL | E7: 02. Transferencia a cuenta bancaria | F7: 0000001820 | G7: Caja y Bancos | H7: 46023 | I7: 202601 Enero 2026 | J7: 24/01/2026 | K7: FE E001-00000267 | L7: FE E001-00000267 | M7: S/ | N7: 252483.54 | O7: 252483.54 | P7: SERVICIO DE ACOMPANAMIENTO Y ASESORIA TECNICO-LEGAL Y GESTIÓN DE RECLAMO PARA LA ORDEN DE CAMBIO 3 EN EL PROYECTO: MEJORAMIENTO DE LA CAPACIDAD RESOLUTIVA DE LOS SERVICIOS DE SALUD DEL HOSPITAL ANTONIO LORENA NIVEL III - CUSCO ETAPA 2. - OBS: CUOTA 13 DE 115 | Q7: COBRANZA DE FACTURA E001-267 | R7: 2026 | S7: 05/01/2026
A8: a | B8: 10410013 BBVA CONTINENTAL MN | C8: 20614395789 | D8: CONSORCIO SALUD HUANCA SANCOS II | E8: 02. Transferencia a cuenta bancaria | F8: 0000001811 | G8: Caja y Bancos | H8: 46023 | I8: 202601 Enero 2026 | J8: 15/01/2026 | K8: FE E001-00000138 | L8: FE E001-00000138 | M8: S/ | N8: 191834.46 | O8: 191834.46 | P8: SERVICIO DE GERENCIAMIENTO TECNICO CONTRACTUAL EN EL PROYECTO: MEJORAMIENTO DE LOS SERVICIOS DEL ESTABLECIMIENTO DE SALUD ESTRATEGICOS HUANCA SANCOS, DISTRITO DE SANCOS - PROVINCIA DE HUANCA SANCOS -DEPARTAMENTO DE AYACUCHO. | Q8: COBRANZA DE FACTURA E001-138 | R8: 2026 | S8: 31/07/2025
A9: a | B9: 10410013 BBVA CONTINENTAL MN | C9: 20607900052 | D9: CONSORCIO SAN MIGUEL | E9: 02. Transferencia a cuenta bancaria | F9: 0000001814 | G9: Caja y Bancos | H9: 46023 | I9: 202601 Enero 2026 | J9: 19/01/2026 | K9: FE E001-00000257 | L9: FE E001-00000257 | M9: S/ | N9: 165229.55 | O9: 165229.55 | P9: SERVICIO DE ASESORIA TECNICO LEGAL ESPECIALIZADA EN ADMINISTRACION CONTRACTUAL EN EL PROY:AMPLIACION Y MEJORAMIENTO DE SISTEMAS AGUA POTABLE Y ALCANTARILLADO EN SECTORES 311,313,330,310,312,314,300,307,319,324 Y 301,DE SJM,VMT Y VES-ETAPA 1 FRENTE 2 - VALORIZACION DE MAYORES GASTOS GENERALES VARIABLES- AMPLIACION DE PLAZO N°28. | Q9: COBRANZA DE FACTURA E001-257 | R9: 2026 | S9: 16/12/2025
A10: a | B10: 10410013 BBVA CONTINENTAL MN | C10: 20513250445 | D10: INMAC PERU S.A.C. | E10: 02. Transferencia a cuenta bancaria | F10: 0000001806 | G10: Caja y Bancos | H10: 46023 | I10: 202601 Enero 2026 | J10: 08/01/2026 | K10: FE E001-00000266 | L10: FE E001-00000266 | M10: S/ | N10: 139577.18 | O10: 139577.18 | P10: SERVICIOS TECNICO-LEGALES QUE COMPRENDEN LA ASESORIA Y PATROCINIO EN LA GESTION DE CONTROVERSIAS FRENTE A LA ANIN EN PROYECTO CHICAMA. | Q10: COBRANZA DE FACTURA E001-266 | R10: 2026 | S10: 31/12/2025
A11: a | B11: 10710021 BANCO NACION - CTA DETRACCION | C11: 20517562158 | D11: CONSTRUCTORA & INMOBILIARIA SAGITARIO Y ASOCIADOS S.A.C. - SAGITARIO & ASOCIADOS S.A.C. | E11: 02. Transferencia a cuenta bancaria | F11: 0000001865 | G11: Caja y Bancos | H11: 46023 | I11: 202601 Enero 2026 | J11: 09/01/2026 | K11: FE E001-00000194 | L11: FE E001-00000194 | M11: S/ | N11: 2124 | O11: 2124 | P11: SERVICIO DE ACOMPANAMIENTO Y ASESORIA TECNICO-LEGAL EN EL PROYECTO: EJECUCION DEL SALDO DE OBRA:MEJORAMIENTO DE LOS SERVICIOS DE SALUD DEL CENTRO DE SALUD MACHUPICCHU,DISTRITO DE MACHUPICCHU,PROVINCIA DE URUBAMBA,DEPARTAMENTO DE CUSCO.CUI 2343148. ACORDE CON ADENDA N° 01 AL CONTRATO N° 12-2024-MACHU. | Q11: Transferencia a Cuenta Bancaria | R11: 2026 | S11: 15/10/2025
A12: a | B12: 10710021 BANCO NACION - CTA DETRACCION | C12: 20517562158 | D12: CONSTRUCTORA & INMOBILIARIA SAGITARIO Y ASOCIADOS S.A.C. - SAGITARIO & ASOCIADOS S.A.C. | E12: 02. Transferencia a cuenta bancaria | F12: 0000001913 | G12: Caja y Bancos | H12: 46023 | I12: 202601 Enero 2026 | J12: 09/01/2026 | K12: FE E001-00000247 | L12: FE E001-00000247 | M12: S/ | N12: 2124 | O12: 2124 | P12: SERVICIO DE ACOMPANAMIENTO Y ASESORIA TECNICO-LEGAL EN EL PROYECTO: EJECUCION DEL SALDO DE OBRA:MEJORAMIENTO DE LOS SERVICIOS DE SALUD DEL CENTRO DE SALUD MACHUPICCHU,DISTRITO DE MACHUPICCHU,PROVINCIA DE URUBAMBA,DEPARTAMENTO DE CUSCO.CUI 2343148. ACORDE CON ADENDA N° 01 AL CONTRATO N° 12-2024-MACHU. | Q12: Transferencia a Cuenta Bancaria | R12: 2026 | S12: 15/12/2025
A13: a | B13: 10710021 BANCO NACION - CTA DETRACCION | C13: 20517562158 | D13: CONSTRUCTORA & INMOBILIARIA SAGITARIO Y ASOCIADOS S.A.C. - SAGITARIO & ASOCIADOS S.A.C. | E13: 02. Transferencia a cuenta bancaria | F13: 0000001862 | G13: Caja y Bancos | H13: 46023 | I13: 202601 Enero 2026 | J13: 09/01/2026 | K13: FE E001-00000193 | L13: FE E001-00000193 | M13: S/ | N13: 2124 | O13: 2124 | P13: SERVICIO DE ACOMPANAMIENTO Y ASESORIA TECNICO-LEGAL EN EL PROYECTO: MEJORAMIENTO Y AMPLIACION DE LOS SERVICIOS DE SALUD DEL ESTABLECIMIENTO DE SALUD TUPAC AMARU,DISTRITO DE TUPAC AMARU,PROV PISCO,DEPARTAMENTO DE ICA. ACORDE CON ADENDA N° 01 AL CONTRATO N° 11-2024-TUPAC. | Q13: Transferencia a Cuenta Bancaria | R13: 2026 | S13: 15/10/2025
A14: a | B14: 10710021 BANCO NACION - CTA DETRACCION | C14: 20517562158 | D14: CONSTRUCTORA & INMOBILIARIA SAGITARIO Y ASOCIADOS S.A.C. - SAGITARIO & ASOCIADOS S.A.C. | E14: 02. Transferencia a cuenta bancaria | F14: 0000001910 | G14: Caja y Bancos | H14: 46023 | I14: 202601 Enero 2026 | J14: 09/01/2026 | K14: FE E001-00000246 | L14: FE E001-00000246 | M14: S/ | N14: 2124 | O14: 2124 | P14: SERVICIO DE ACOMPANAMIENTO Y ASESORIA TECNICO-LEGAL EN EL PROYECTO: MEJORAMIENTO Y AMPLIACION DE LOS SERVICIOS DE SALUD DEL ESTABLECIMIENTO DE SALUD TUPAC AMARU,DISTRITO DE TUPAC AMARU,PROV PISCO,DEPARTAMENTO DE ICA. ACORDE CON ADENDA N° 01 AL CONTRATO N° 11-2024-TUPAC. | Q14: Transferencia a Cuenta Bancaria | R14: 2026 | S14: 15/12/2025
A15: a | B15: 10710021 BANCO NACION - CTA DETRACCION | C15: 20517562158 | D15: CONSTRUCTORA & INMOBILIARIA SAGITARIO Y ASOCIADOS S.A.C. - SAGITARIO & ASOCIADOS S.A.C. | E15: 02. Transferencia a cuenta bancaria | F15: 0000001871 | G15: Caja y Bancos | H15: 46023 | I15: 202601 Enero 2026 | J15: 09/01/2026 | K15: FE E001-00000196 | L15: FE E001-00000196 | M15: S/ | N15: 2124 | O15: 2124 | P15: SERVICIO DE ACOMPANAMIENTO Y ASESORIA TECNICO-LEGAL EN EL PROYECTO: MEJORAMIENTO Y AMPLIACION E LOS SERVICIOS DE SALUD DEL ESTABLECIMIENTO DE SALUD APOYO PALPA,DISTRITO DE PALPA, PROV DE PALPA,DEPARTAMENTO DE ICA. ACORDE CON ADENDA N° 01 AL CONTRATO N° 14-2024-PALPA. | Q15: Transferencia a Cuenta Bancaria | R15: 2026 | S15: 15/10/2025
A16: a | B16: 10710021 BANCO NACION - CTA DETRACCION | C16: 20517562158 | D16: CONSTRUCTORA & INMOBILIARIA SAGITARIO Y ASOCIADOS S.A.C. - SAGITARIO & ASOCIADOS S.A.C. | E16: 02. Transferencia a cuenta bancaria | F16: 0000001919 | G16: Caja y Bancos | H16: 46023 | I16: 202601 Enero 2026 | J16: 09/01/2026 | K16: FE E001-00000249 | L16: FE E001-00000249 | M16: S/ | N16: 2124 | O16: 2124 | P16: SERVICIO DE ACOMPANAMIENTO Y ASESORIA TECNICO-LEGAL EN EL PROYECTO: MEJORAMIENTO Y AMPLIACION E LOS SERVICIOS DE SALUD DEL ESTABLECIMIENTO DE SALUD APOYO PALPA,DISTRITO DE PALPA, PROV DE PALPA,DEPARTAMENTO DE ICA. ACORDE CON ADENDA N° 01 AL CONTRATO N° 14-2024-PALPA. | Q16: Transferencia a Cuenta Bancaria | R16: 2026 | S16: 15/12/2025
A17: a | B17: 10710021 BANCO NACION - CTA DETRACCION | C17: 20517562158 | D17: CONSTRUCTORA & INMOBILIARIA SAGITARIO Y ASOCIADOS S.A.C. - SAGITARIO & ASOCIADOS S.A.C. | E17: 02. Transferencia a cuenta bancaria | F17: 0000001877 | G17: Caja y Bancos | H17: 46023 | I17: 202601 Enero 2026 | J17: 09/01/2026 | K17: FE E001-00000198 | L17: FE E001-00000198 | M17: S/ | N17: 2124 | O17: 2124 | P17: SERVICIO DE ACOMPANAMIENTO Y ASESORIA TECNICO-LEGAL EN PROY: CONTRAT.DE LA EJECUCION DE LA OBRA:MEJORAMIENTO DE LA CAPACIDAD RESOLUTIVA DE LOS SERVICIOS DE SALUD DEL HOSPITAL DE FERREÑAFE,DIST. FERREÑAFE,PROV.FERREÑAFE,REGION LAMBAYEQUE.CUI 2310820. ACORDE AL CONTRATO DE PRESTACION DE SERVICIOS DE ASESORIA TECNICO-LEGAL N° 16- 2025-FERREÑAFE. | Q17: Transferencia a Cuenta Bancaria | R17: 2026 | S17: 15/10/2025
... A85: a | B85: 10410013 BBVA CONTINENTAL MN | C85: 20613390996 | D85: CONSORCIO HEALTH BERNALES | E85: 02. Transferencia a cuenta bancaria | F85: 0000001002 | G85: Caja y Bancos | H85: 46082 | I85: 202603 Marzo 2026 | J85: 01/03/2026 | K85: FE E001-00000315 | L85: FE E001-00000315 | M85: S/ | N85: 519200 | O85: 519200 | P85: SERVICIO DE ASESORIA INTEGRAL EN LA ADMINISTRACION CONTRACTUAL PARA EL PROCESO: DISEÑO CONSTRUCCION Y EQUIPAMIENTO DEL NUEVO HOSPITAL NACIONAL SERGIO BERNALES, LOCALIDAD DE COLLIQUE, DISTRITO DE COMAS, PROVINCIA DE LIMA - SEGUN ADENDA AL CONTRATO 003.2024/CH-1 // SERVICIO CORRESPONDIENTE AL MES DE ENERO 2026. | Q85: FECHA VALOR 28/02 EECC REFLEJADO EN MARZO | R85: 2026 | S85: 18/02/2026
A86: Total a | O86: =SUBTOTAL(9,O6:O85) -> 5560371.2
A87: b | B87: 10410014 BBVA CONTINENTAL ME | D87: YUPANQUI ARTADI, REYNALDO RICARDO | E87: 02. Transferencia a cuenta bancaria | F87: 0000002098 | G87: Caja y Bancos | H87: 46023 | I87: 202601 Enero 2026 | J87: 26/01/2026 | K87: PR 0000000607 | L87: PR 0000000607 | M87: U$ | N87: 45000 | O87: 151155 | P87: PRESTAMO DE REYNALDO A INTEGRAL | Q87: Transferencia a Cuenta Bancaria | R87: 2026 | S87: 26/01/2026
A88: b | B88: 10410014 BBVA CONTINENTAL ME | D88: YUPANQUI ARTADI, REYNALDO RICARDO | E88: 02. Transferencia a cuenta bancaria | F88: 0000002099 | G88: Caja y Bancos | H88: 46023 | I88: 202601 Enero 2026 | J88: 26/01/2026 | K88: PR 0000000608 | L88: PR 0000000608 | M88: U$ | N88: 45000 | O88: 151155 | P88: PRESTAMO DE REYNALDO A INTEGRAL | Q88: Transferencia a Cuenta Bancaria | R88: 2026 | S88: 26/01/2026
A89: b | B89: 10410013 BBVA CONTINENTAL MN | D89: YUPANQUI ARTADI, REYNALDO RICARDO | E89: 02. Transferencia a cuenta bancaria | F89: 0000002090 | G89: Caja y Bancos | H89: 46023 | I89: 202601 Enero 2026 | J89: 19/01/2026 | K89: PR 0000000589 | L89: PR 0000000589 | M89: S/ | N89: 105000 | O89: 105000 | P89: PRESTAMO DE RY ( ICYS) | Q89: PRESTAMO DE ICYS RY | R89: 2026 | S89: 19/01/2026
A90: b | B90: 10410014 BBVA CONTINENTAL ME | D90: YUPANQUI ARTADI, REYNALDO RICARDO | E90: 02. Transferencia a cuenta bancaria | F90: 0000000609 | G90: Caja y Bancos | H90: 46054 | I90: 202602 Febrero 2026 | J90: 07/02/2026 | K90: PR 0000000639 | L90: PR 0000000639 | M90: U$ | N90: 11850 | O90: 39851.55 | P90: PRESTAMO DE REYNALDO A INTEGRAL | Q90: PRESTAMO DE RY | R90: 2026 | S90: 07/02/2026
A91: b | B91: 10410013 BBVA CONTINENTAL MN | C91: 10415120911 | D91: GUTIERREZ ACQUARONE, GUSTAVO | E91: 02. Transferencia a cuenta bancaria | F91: 0000000605 | G91: Caja y Bancos | H91: 46054 | I91: 202602 Febrero 2026 | J91: 17/02/2026 | K91: DEV 0000000018 | L91: DEV 0000000018 | M91: S/ | N91: 204 | O91: 204 | P91: DEVOLUCION DE ER GG | Q91: DEVOLUCION DE ER | R91: 2026 | S91: 17/02/2026
A92: b | B92: 10410014 BBVA CONTINENTAL ME | E92: 14. Diferencia de cambio - Cuentas | F92: 0000000380 | G92: Diferencia de Cambio | H92: 46054 | I92: 202602 Febrero 2026 | J92: 28/02/2026 | M92: U$ | N92: 0 | O92: 439.12 | P92: Diferencia de cambio - Por Cuenta | Q92: Diferencia de cambio - Por Cuenta | R92: 2026 | S92: 28/02/2026
A93: b | B93: 10410013 BBVA CONTINENTAL MN | C93: 10074121395 | D93: JONES PATRONI, GUILLERMO AUGUSTO | E93: 02. Transferencia a cuenta bancaria | F93: 0000000876 | G93: Caja y Bancos | H93: 46082 | I93: 202603 Marzo 2026 | J93: 13/03/2026 | K93: DEV 0000000019 | L93: DEV 0000000019 | M93: S/ | N93: 3.12 | O93: 3.12 | P93: DEVOLUCION DE ER WILLY JONES | Q93: Transferencia a Cuenta Bancaria | R93: 2026 | S93: 13/03/2026
A94: b | B94: 10410014 BBVA CONTINENTAL ME | C94: 20536612972 | D94: CMO GROUP S.A. | E94: 02. Transferencia a cuenta bancaria | F94: 0000000822 | G94: Caja y Bancos | H94: 46082 | I94: 202603 Marzo 2026 | J94: 04/03/2026 | K94: DP 0000000030 | L94: DP 0000000030 | M94: U$ | N94: 95948 | O94: 326990.78 | P94: INGRESOS DE CMO SEGUN EECC (O.PAGO REC EXT LIQ:9675785) | Q94: INGRESOS CMO | R94: 2026 | S94: 04/03/2026
A95: b | B95: 10410014 BBVA CONTINENTAL ME | E95: 14. Diferencia de cambio - Cuentas | F95: 0000000485 | G95: Diferencia de Cambio | H95: 46082 | I95: 202603 Marzo 2026 | J95: 31/03/2026 | M95: U$ | N95: 0 | O95: 140.3 | P95: Diferencia de cambio - Por Cuenta | Q95: Diferencia de cambio - Por Cuenta | R95: 2026 | S95: 31/03/2026
A96: Total b | O96: =SUBTOTAL(9,O87:O95) -> 774938.87
A97: c | B97: 10410013 BBVA CONTINENTAL MN | C97: 10443226350 | D97: PACHECO CHUQUILIN, JEANETH CRISTY | E97: 03. Pago | F97: 0000000124 | G97: Libro Diario | H97: 46023 | I97: 202601 Enero 2026 | J97: 08/01/2026 | K97: RH E001-0000000009 | L97: RH E001-0000000009 | M97: S/ | N97: -1039.6 | O97: -1039.6 | P97: CAPACITACION EN SISTEMA ERP S10 POR LOS MESES DE NOVIEMBRE Y DICIEMBRE DEL 2025. | Q97: PAGO DE SERV. HONORARIOS JP | R97: 2026 | S97: 08/01/2026
A98: c | B98: 10410013 BBVA CONTINENTAL MN | C98: 15608157376 | D98: VELASQUEZ PEREZ, JUAN PABLO | E98: 03. Pago | F98: 0000000139 | G98: Libro Diario | H98: 46023 | I98: 202601 Enero 2026 | J98: 30/01/2026 | K98: RH E001-0000000033 | L98: RH E001-0000000033 | M98: S/ | N98: -6600 | O98: -6600 | P98: SERVICIO DE REVISION Y EDICION DE VIDEO EN TEMPORADA NAVIDEÑA 2025 | Q98: 30/01 PAGO DE SERV. HONORARIOS ENERO 2026 | R98: 2026 | S98: 30/01/2026
A99: c | B99: 10410014 BBVA CONTINENTAL ME | C99: 10103167154 | D99: INDACOCHEA CACEDA, FELIX ALEJANDRO | E99: 03. Pago | F99: 0000000146 | G99: Libro Diario | H99: 46023 | I99: 202601 Enero 2026 | J99: 30/01/2026 | K99: RH E001-0000000048 | L99: RH E001-0000000048 | M99: U$ | N99: -2760 | O99: -9232.2 | P99: ASESORIA DE ESTRUCTURACIÓN FINANCIERA - DICIEMBRE 2025 | Q99: PAGO DE SERV. DIETAS INDACOCHEA | R99: 2026 | S99: 30/01/2026
A100: c | B100: 10410013 BBVA CONTINENTAL MN | C100: 10460865528 | D100: MEDINA FLORES, JUAN CARLOS | E100: 03. Pago | F100: 0000000127 | G100: Libro Diario | H100: 46023 | I100: 202601 Enero 2026 | J100: 30/01/2026 | K100: RH E001-0000000109 | L100: RH E001-0000000109 | M100: S/ | N100: -26864 | O100: -26864 | P100: SERVICIO DE CONSULTORIA LEGAL ESPECIALIZADA EN GESTION CONTRACTUAL - ENERO 2026 | Q100: PAGO DE SERV. HONORARIOS JCM ENERO 2026 | R100: 2026 | S100: 30/01/2026
A101: c | B101: 10410013 BBVA CONTINENTAL MN | C101: 10094866249 | D101: MEDINA AIQUIPA, DAVID BERNABE | E101: 03. Pago | F101: 0000000130 | G101: Libro Diario | H101: 46023 | I101: 202601 Enero 2026 | J101: 30/01/2026 | K101: RH E001-0000000240 | L101: RH E001-0000000240 | M101: S/ | N101: -20000 | O101: -20000 | P101: SERVICIO DE ASESORIA EN GESTION CONTRACTUAL DE OBRAS PÚBLICAS MES DE ENERO 2026 | Q101: PAGO DE SERV. HONORARIOS DM Y AC ENERO 2026 | R101: 2026 | S101: 30/01/2026
A102: c | B102: 10410014 BBVA CONTINENTAL ME | C102: 10087738545 | D102: BARRIOS FERNANDEZ, CONCHA RAUL HERNANDO MARTIN | E102: 03. Pago | F102: 0000000143 | G102: Libro Diario | H102: 46023 | I102: 202601 Enero 2026 | J102: 30/01/2026 | K102: RH E001-0000000260 | L102: RH E001-0000000260 | M102: U$ | N102: -4600 | O102: -15387 | P102: DIETA DE DIRECTORIO | Q102: PAGO DE SERV. DIETAS BARRIOS | R102: 2026 | S102: 30/01/2026
A103: c | B103: 10410013 BBVA CONTINENTAL MN | C103: 20100130204 | D103: BANCO CONTINENTAL | E103: 03. Pago | F103: 0000002062 | G103: Libro Diario | H103: 46023 | I103: 202601 Enero 2026 | J103: 30/01/2026 | K103: RPR -0054951777 | L103: RPR 0054951777 | M103: S/ | N103: -1500 | O103: -1500 | P103: PLANILLA DE PAGO PRACTICANTES | Q103: 30/01 PLANILLA DE PRACTICANTES | R103: 2026 | S103: 30/01/2026
A104: c | B104: 10410013 BBVA CONTINENTAL MN | C104: 20100047218 | D104: BANCO DE CREDITO DEL PERU | E104: 03. Pago | F104: 0000002063 | G104: Libro Diario | H104: 46023 | I104: 202601 Enero 2026 | J104: 30/01/2026 | K104: RPR -0054951778 | L104: RPR 0054951778 | M104: S/ | N104: -1130 | O104: -1130 | P104: PLANILLA DE PAGO PRACTICANTES | Q104: 30/01 PLANILLA DE PRACTICANTES | R104: 2026 | S104: 30/01/2026
A105: c | B105: 10410013 BBVA CONTINENTAL MN | C105: 20100130204 | D105: BANCO CONTINENTAL | E105: 03. Pago | F105: 0000002087 | G105: Libro Diario | H105: 46023 | I105: 202601 Enero 2026 | J105: 30/01/2026 | K105: RPR 0054951783 | L105: RPR 0054951783 | M105: S/ | N105: -148170.82 | O105: -148170.82 | P105: PLANILLA DE PAGO EMPLEADOS | Q105: 30/01 PLANILLA ENERO EMPLEADOS | R105: 2026 | S105: 30/01/2026
A106: c | B106: 10410013 BBVA CONTINENTAL MN | C106: 20100130204 | D106: BANCO CONTINENTAL | E106: 03. Pago | F106: 0000002088 | G106: Libro Diario | H106: 46023 | I106: 202601 Enero 2026 | J106: 30/01/2026 | K106: RPR 0054951783 | L106: RPR 0054951783 | M106: S/ | N106: -7661.61 | O106: -7661.61 | P106: PLANILLA DE PAGO EMPLEADOS | Q106: 30/01 PLANILLA ENERO EMPLEADOS O/B | R106: 2026 | S106: 30/01/2026
A107: c | B107: 10410013 BBVA CONTINENTAL MN | C107: 20100053455 | D107: BANCO INTERNACIONAL DEL PERU - INTERBANK | E107: 03. Pago | F107: 0000002088 | G107: Libro Diario | H107: 46023 | I107: 202601 Enero 2026 | J107: 30/01/2026 | K107: RPR -0054951784 | L107: RPR 0054951784 | M107: S/ | N107: -8199.64 | O107: -8199.64 | P107: PLANILLA DE PAGO EMPLEADOS | Q107: 30/01 PLANILLA ENERO EMPLEADOS O/B | R107: 2026 | S107: 30/01/2026
...

Sheet Detalle S10_Junio 2026 (2)
A1: Item | B1: Cuenta Contable | C1: RUC Socio de Negocio | D1: Socio de Negocio | E1: Procedencia | F1: N° Asiento | G1: Libro | H1: Mes | I1: Periodo Contable | J1: Fecha de Transacción | K1: N° Documento | L1: N° Documento Pago | M1: MO | N1: Saldo Origen | O1: Saldo ( S/ ) | P1: Observación Documento | Q1: Observación | R1: Año | S1: F.Emisión
A2: d | B2: 10410013 BBVA CONTINENTAL MN | C2: 20100130204 | D2: BANCO CONTINENTAL | E2: 03. Pago | F2: 0000001963 | G2: Libro Diario | H2: 46023 | I2: 202601 Enero 2026 | J2: 30/01/2026 | K2: AP 0000000257 | L2: AP 0000000257 | M2: S/ | N2: -1 | O2: -1 | P2: COMISIONES BANCARIAS ENERO SOLES | Q2: PAGO DE COMISIONES MENSUALES ENERO 2026 | R2: 2026 | S2: 30/01/2026
A3: d | B3: 10410013 BBVA CONTINENTAL MN | C3: 20100130204 | D3: BANCO CONTINENTAL | E3: 03. Pago | F3: 0000001964 | G3: Libro Diario | H3: 46023 | I3: 202601 Enero 2026 | J3: 30/01/2026 | K3: AP 0000000257 | L3: AP 0000000257 | M3: S/ | N3: -1 | O3: -1 | P3: COMISIONES BANCARIAS ENERO SOLES | Q3: PAGO DE COMISIONES MENSUALES ENERO 2026 | R3: 2026 | S3: 30/01/2026
A4: d | B4: 10410013 BBVA CONTINENTAL MN | C4: 20100130204 | D4: BANCO CONTINENTAL | E4: 03. Pago | F4: 0000001943 | G4: Libro Diario | H4: 46023 | I4: 202601 Enero 2026 | J4: 08/01/2026 | K4: AP 0000000257 | L4: AP 0000000257 | M4: S/ | N4: -3.5 | O4: -3.5 | P4: COMISIONES BANCARIAS ENERO SOLES | Q4: PAGO DE COMISIONES MENSUALES ENERO 2026 | R4: 2026 | S4: 08/01/2026
A5: d | B5: 10410013 BBVA CONTINENTAL MN | C5: 20100130204 | D5: BANCO CONTINENTAL | E5: 03. Pago | F5: 0000001944 | G5: Libro Diario | H5: 46023 | I5: 202601 Enero 2026 | J5: 08/01/2026 | K5: AP 0000000257 | L5: AP 0000000257 | M5: S/ | N5: -3.5 | O5: -3.5 | P5: COMISIONES BANCARIAS ENERO SOLES | Q5: PAGO DE COMISIONES MENSUALES ENERO 2026 | R5: 2026 | S5: 08/01/2026
A6: d | B6: 10410013 BBVA CONTINENTAL MN | C6: 20100130204 | D6: BANCO CONTINENTAL | E6: 03. Pago | F6: 0000001945 | G6: Libro Diario | H6: 46023 | I6: 202601 Enero 2026 | J6: 08/01/2026 | K6: AP 0000000257 | L6: AP 0000000257 | M6: S/ | N6: -3.5 | O6: -3.5 | P6: COMISIONES BANCARIAS ENERO SOLES | Q6: PAGO DE COMISIONES MENSUALES ENERO 2026 | R6: 2026 | S6: 08/01/2026
A7: d | B7: 10410013 BBVA CONTINENTAL MN | C7: 20100130204 | D7: BANCO CONTINENTAL | E7: 03. Pago | F7: 0000001946 | G7: Libro Diario | H7: 46023 | I7: 202601 Enero 2026 | J7: 08/01/2026 | K7: AP 0000000257 | L7: AP 0000000257 | M7: S/ | N7: -3.5 | O7: -3.5 | P7: COMISIONES BANCARIAS ENERO SOLES | Q7: PAGO DE COMISIONES MENSUALES ENERO 2026 | R7: 2026 | S7: 08/01/2026
A8: d | B8: 10410013 BBVA CONTINENTAL MN | C8: 20100130204 | D8: BANCO CONTINENTAL | E8: 03. Pago | F8: 0000001947 | G8: Libro Diario | H8: 46023 | I8: 202601 Enero 2026 | J8: 08/01/2026 | K8: AP 0000000257 | L8: AP 0000000257 | M8: S/ | N8: -3.5 | O8: -3.5 | P8: COMISIONES BANCARIAS ENERO SOLES | Q8: PAGO DE COMISIONES MENSUALES ENERO 2026 | R8: 2026 | S8: 08/01/2026
A9: d | B9: 10410013 BBVA CONTINENTAL MN | C9: 20100130204 | D9: BANCO CONTINENTAL | E9: 03. Pago | F9: 0000001948 | G9: Libro Diario | H9: 46023 | I9: 202601 Enero 2026 | J9: 08/01/2026 | K9: AP 0000000257 | L9: AP 0000000257 | M9: S/ | N9: -3.5 | O9: -3.5 | P9: COMISIONES BANCARIAS ENERO SOLES | Q9: PAGO DE COMISIONES MENSUALES ENERO 2026 | R9: 2026 | S9: 08/01/2026
A10: d | B10: 10410013 BBVA CONTINENTAL MN | C10: 20100130204 | D10: BANCO CONTINENTAL | E10: 03. Pago | F10: 0000001949 | G10: Libro Diario | H10: 46023 | I10: 202601 Enero 2026 | J10: 08/01/2026 | K10: AP 0000000257 | L10: AP 0000000257 | M10: S/ | N10: -3.5 | O10: -3.5 | P10: COMISIONES BANCARIAS ENERO SOLES | Q10: PAGO DE COMISIONES MENSUALES ENERO 2026 | R10: 2026 | S10: 08/01/2026
A11: d | B11: 10410013 BBVA CONTINENTAL MN | C11: 20100130204 | D11: BANCO CONTINENTAL | E11: 03. Pago | F11: 0000001950 | G11: Libro Diario | H11: 46023 | I11: 202601 Enero 2026 | J11: 08/01/2026 | K11: AP 0000000257 | L11: AP 0000000257 | M11: S/ | N11: -3.5 | O11: -3.5 | P11: COMISIONES BANCARIAS ENERO SOLES | Q11: PAGO DE COMISIONES MENSUALES ENERO 2026 | R11: 2026 | S11: 08/01/2026
A12: d | B12: 10410013 BBVA CONTINENTAL MN | C12: 20100130204 | D12: BANCO CONTINENTAL | E12: 03. Pago | F12: 0000001951 | G12: Libro Diario | H12: 46023 | I12: 202601 Enero 2026 | J12: 08/01/2026 | K12: AP 0000000257 | L12: AP 0000000257 | M12: S/ | N12: -3.5 | O12: -3.5 | P12: COMISIONES BANCARIAS ENERO SOLES | Q12: PAGO DE COMISIONES MENSUALES ENERO 2026 | R12: 2026 | S12: 08/01/2026
A13: d | B13: 10410013 BBVA CONTINENTAL MN | C13: 20100130204 | D13: BANCO CONTINENTAL | E13: 03. Pago | F13: 0000001952 | G13: Libro Diario | H13: 46023 | I13: 202601 Enero 2026 | J13: 08/01/2026 | K13: AP 0000000257 | L13: AP 0000000257 | M13: S/ | N13: -3.5 | O13: -3.5 | P13: COMISIONES BANCARIAS ENERO SOLES | Q13: PAGO DE COMISIONES MENSUALES ENERO 2026 | R13: 2026 | S13: 08/01/2026
... A49: d | B49: 10410014 BBVA CONTINENTAL ME | C49: 20100130204 | D49: BANCO CONTINENTAL | E49: 03. Pago | F49: 0000002126 | G49: Libro Diario | H49: 46023 | I49: 202601 Enero 2026 | J49: 30/01/2026 | K49: DP 0000000952 | L49: DP 0000000952 | M49: U$ | N49: -11.35 | O49: -37.97 | P49: ITF ENERO DOLARES | Q49: 01/01 COMISIONES BANCARIAS DE ENERO | R49: 2026 | S49: 30/01/2026
A50: d | B50: 10410014 BBVA CONTINENTAL ME | D50: CORNEJO DAVILA, VANINNA JUISA | E50: 03. Pago | F50: 0000002106 | G50: Libro Diario | H50: 46023 | I50: 202601 Enero 2026 | J50: 26/01/2026 | K50: PR 0000000602 | L50: PR 0000000602 | M50: U$ | N50: -90000 | O50: -302310 | P50: PRESTAMO A VC | Q50: 26/01 PRESTAMO A VC | R50: 2026 | S50: 26/01/2026
A51: d | B51: 10410013 BBVA CONTINENTAL MN | D51: YUPANQUI ARTADI, REYNALDO RICARDO | E51: 03. Pago | F51: 0000002003 | G51: Libro Diario | H51: 46023 | I51: 202601 Enero 2026 | J51: 14/01/2026 | K51: PR 0000000588 | L51: PR 0000000588 | M51: S/ | N51: -210000 | O51: -210000 | P51: PRESTAMO A RYA - CALIDAD Y GESTION | Q51: 14/01 PRESTAMO CALIDAD Y GESTION RY | R51: 2026 | S51: 14/01/2026
A52: d | B52: 10410013 BBVA CONTINENTAL MN | C52: 20601546478 | D52: PANORAMICA TECHNOLOGY S.A.C. | E52: 03. Pago | F52: 0000002049 | G52: Libro Diario | H52: 46023 | I52: 202601 Enero 2026 | J52: 30/01/2026 | K52: AP 0000000261 | L52: AP 0000000261 | M52: S/ | N52: -78735.9 | O52: -78735.9 | P52: ADELANTO PARA CULMINACION DE TRABAJO DE SISTEMA DE COMUNICACIONES | Q52: 30/01 PAGO A PROVEEDORES | R52: 2026 | S52: 30/01/2026
A53: d | B53: 10410014 BBVA CONTINENTAL ME | C53: 20536612972 | D53: CMO GROUP S.A. | E53: 03. Pago | F53: 0000002115 | G53: Libro Diario | H53: 46023 | I53: 202601 Enero 2026 | J53: 30/01/2026 | K53: PR 0000000605 | L53: PR 0000000605 | M53: U$ | N53: -15000 | O53: -50175 | P53: PRESTAMO A CMO // ANCONA | Q53: 30/01 PRESTAMO A CMO: ANCONA | R53: 2026 | S53: 30/01/2026
A54: d | B54: 10410013 BBVA CONTINENTAL MN | C54: 10097521889 | D54: GOMERO ROJAS, GUILLERMO ALBERTO | E54: 03. Pago | F54: 0000002086 | G54: Libro Diario | H54: 46023 | I54: 202601 Enero 2026 | J54: 13/01/2026 | K54: PR 0000000600 | L54: PR 0000000600 | M54: S/ | N54: -45000 | O54: -45000 | P54: PRESTAMO A GG - SERV. GENERALES C&C | Q54: 13/01 PRESTAMO A GG - SERV. GENERALES | R54: 2026 | S54: 13/01/2026
A55: d | B55: 10410014 BBVA CONTINENTAL ME | C55: 20536612972 | D55: CMO GROUP S.A. | E55: 03. Pago | F55: 0000002113 | G55: Libro Diario | H55: 46023 | I55: 202601 Enero 2026 | J55: 30/01/2026 | K55: PR 0000000603 | L55: PR 0000000603 | M55: U$ | N55: -11800 | O55: -39471 | P55: PRESTAMO A CMO // ESTUDIO CARO F002-434 | Q55: 30/01 PRESTAMO A CMO: ESTUDIO CARO | R55: 2026 | S55: 30/01/2026
A56: d | B56: 10410013 BBVA CONTINENTAL MN | C56: 20536612972 | D56: CMO GROUP S.A. | E56: 03. Pago | F56: 0000002020 | G56: Libro Diario | H56: 46023 | I56: 202601 Enero 2026 | J56: 30/01/2026 | K56: PR 0000000590 | L56: PR 0000000590 | M56: S/ | N56: -27652.11 | O56: -27652.11 | P56: PRESTAMO A CMO: PLANILLA ENERO | Q56: 30/01 PRESTAMO A CMO: PLANILLA ENERO 26 | R56: 2026 | S56: 30/01/2026
A57: d | B57: 10410013 BBVA CONTINENTAL MN | C57: 20536612972 | D57: CMO GROUP S.A. | E57: 03. Pago | F57: 0000002078 | G57: Libro Diario | H57: 46023 | I57: 202601 Enero 2026 | J57: 30/01/2026 | K57: PR 0000000596 | L57: PR 0000000596 | M57: S/ | N57: -25000 | O57: -25000 | P57: PRESTAMO A CMO POR PAGO A PROVEEDORES - LBS | Q57: 30/01 PRESTAMO A CMO: PAGO A PROVEEDORES | R57: 2026 | S57: 30/01/2026
A58: d | B58: 10410013 BBVA CONTINENTAL MN | C58: 20536612972 | D58: CMO GROUP S.A. | E58: 03. Pago | F58: 0000002016 | G58: Libro Diario | H58: 46023 | I58: 202601 Enero 2026 | J58: 20/01/2026 | K58: PR 0000000595 | L58: PR 0000000595 | M58: S/ | N58: -20000 | O58: -20000 | P58: PRESTAMO A CMO // IMPUESTOS | Q58: 20/01 PRESTAMO A CMO: IMPUESTOS | R58: 2026 | S58: 20/01/2026
A59: d | B59: 10410013 BBVA CONTINENTAL MN | C59: 20536612972 | D59: CMO GROUP S.A. | E59: 03. Pago | F59: 0000002070 | G59: Libro Diario | H59: 46023 | I59: 202601 Enero 2026 | J59: 30/01/2026 | K59: PR 0000000596 | L59: PR 0000000596 | M59: S/ | N59: -20000 | O59: -20000 | P59: PRESTAMO A CMO POR PAGO A PROVEEDORES - LBS | Q59: 30/01 PRESTAMO A CMO: PAGO A PROVEEDORES | R59: 2026 | S59: 30/01/2026
A60: d | B60: 10410013 BBVA CONTINENTAL MN | C60: 20536612972 | D60: CMO GROUP S.A. | E60: 03. Pago | F60: 0000002071 | G60: Libro Diario | H60: 46023 | I60: 202601 Enero 2026 | J60: 30/01/2026 | K60: PR 0000000596 | L60: PR 0000000596 | M60: S/ | N60: -20000 | O60: -20000 | P60: PRESTAMO A CMO POR PAGO A PROVEEDORES - LBS | Q60: 30/01 PRESTAMO A CMO: PAGO A PROVEEDORES | R60: 2026 | S60: 30/01/2026
A61: d | B61: 10410013 BBVA CONTINENTAL MN | C61: 20536612972 | D61: CMO GROUP S.A. | E61: 03. Pago | F61: 0000002079 | G61: Libro Diario | H61: 46023 | I61: 202601 Enero 2026 | J61: 30/01/2026 | K61: PR 0000000596 | L61: PR 0000000596 | M61: S/ | N61: -20000 | O61: -20000 | P61: PRESTAMO A CMO POR PAGO A PROVEEDORES - LBS | Q61: 30/01 PRESTAMO A CMO: PAGO A PROVEEDORES | R61: 2026 | S61: 30/01/2026
A62: d | B62: 10410013 BBVA CONTINENTAL MN | C62: 20431115825 | D62: PACIFICO SA ENT PRESTADORA DE SALUD | E62: 03. Pago | F62: 0000002043 | G62: Libro Diario | H62: 46023 | I62: 202601 Enero 2026 | J62: 30/01/2026 | K62: F F027-01053589 | L62: F F027-01053589 | M62: S/ | N62: -18563.68 | O62: -18563.68 | P62: SEGURO EPS // A/COB 9985023 // DOC R-4344398 // VIGENCIA 01/01/2026 AL 31/01/2026 | Q62: 30/01 PAGO A PROVEEDORES | R62: 2026 | S62: 30/01/2026
A63: d | B63: 10410013 BBVA CONTINENTAL MN | C63: 20536612972 | D63: CMO GROUP S.A. | E63: 03. Pago | F63: 0000002074 | G63: Libro Diario | H63: 46023 | I63: 202601 Enero 2026 | J63: 30/01/2026 | K63: PR 0000000596 | L63: PR 0000000596 | M63: S/ | N63: -16875 | O63: -16875 | P63: PRESTAMO A CMO POR PAGO A PROVEEDORES - LBS | Q63: 30/01 PRESTAMO A CMO: PAGO A PROVEEDORES | R63: 2026 | S63: 30/01/2026
... A124: d | B124: 10410013 BBVA CONTINENTAL MN | C124: 10088768197 | D124: BALAREZO ELIAS DE TIRADO, ANA GABRIELA | E124: 03. Pago | F124: 0000002004 | G124: Libro Diario | H124: 46023 | I124: 202601 Enero 2026 | J124: 19/01/2026 | K124: R 0000000001 | L124: R 0000000001 | M124: S/ | N124: -624.33 | O124: -624.33 | P124: CAJA CHICA - INTEGRAL // SEGUN CORREO 19.09.24 | Q124: 19/01 REEMBOLSO CAJA CHICA | R124: 2026 | S124: 19/01/2026
A125: d | B125: 10410013 BBVA CONTINENTAL MN | C125: 10000620471 | D125: VELASQUEZ URREGO, JUAN CARLOS | E125: 03. Pago | F125: 0000002051 | G125: Libro Diario | H125: 46023 | I125: 202601 Enero 2026 | J125: 30/01/2026 | M125: S/ | N125: -611.79 | O125: -611.79 | P125: 30/01 REEMBOLSO A COLABORADORES | Q125: 30/01 REEMBOLSO A COLABORADORES | R125: 2026 | S125: 30/01/2026
A126: d | B126: 10410013 BBVA CONTINENTAL MN | C126: 10771013193 | D126: CCORISAPRA MUÑOZ, ALEXNIEL | E126: 03. Pago | F126: 0000000130 | G126: Libro Diario | H126: 46023 | I126: 202601 Enero 2026 | J126: 30/01/2026 | K126: AP 0000000240 | L126: AP 0000000240 | M126: S/ | N126: -600 | O126: -600 | P126: ADELANTO POR SERVICIO ENERO 2026 | Q126: PAGO DE SERV. HONORARIOS DM Y AC ENERO 2026 | R126: 2026 | S126: 30/01/2026
A127: d | B127: 10410013 BBVA CONTINENTAL MN | C127: 10088768197 | D127: BALAREZO ELIAS DE TIRADO, ANA GABRIELA | E127: 03. Pago | F127: 0000002146 | G127: Libro Diario | H127: 46023 | I127: 202601 Enero 2026 | J127: 30/01/2026 | K127: R 0000000001 | L127: R 0000000001 | M127: S/ | N127: -581.9 | O127: -581.9 | P127: CAJA CHICA - INTEGRAL // SEGUN CORREO 19.09.24 | Q127: 30/01 REEMBOLSO DE CAJA CHICA | R127: 2026 | S127: 30/01/2026
A128: d | B128: 10410013 BBVA CONTINENTAL MN | C128: 20418896915 | D128: MAPFRE PERU COMPAÑIA DE SEGUROS Y REASEGUROS | E128: 03. Pago | F128: 0000002039 | G128: Libro Diario | H128: 46023 | I128: 202601 Enero 2026 | J128: 30/01/2026 | K128: F F050-00749220 | L128: F F050-00749220 | M128: S/ | N128: -580.04 | O128: -580.04 | P128: SEGURO SCTR PENSIONES VALIDO DE 01/01/2026 AL 31/01/2026 - CT CANCELACION RECIBO 167389355 | Q128: 30/01 PAGO A PROVEEDORES | R128: 2026 | S128: 30/01/2026
A129: d | B129: 10410013 BBVA CONTINENTAL MN | C129: 20536612972 | D129: CMO GROUP S.A. | E129: 03. Pago | F129: 0000002065 | G129: Libro Diario | H129: 46023 | I129: 202601 Enero 2026 | J129: 30/01/2026 | K129: PR 0000000596 | L129: PR 0000000596 | M129: S/ | N129: -457.21 | O129: -457.21 | P129: PRESTAMO A CMO POR PAGO A PROVEEDORES - LBS | Q129: 30/01 PRESTAMO A CMO: PAGO A PROVEEDORES | R129: 2026 | S129: 30/01/2026
A130: d | B130: 10410013 BBVA CONTINENTAL MN | C130: 10422397596 | D130: TALLEDO GILVONIO MANUEL OMAR | E130: 03. Pago | F130: 0000000039 | G130: Libro Diario | H130: 46023 | I130: 202601 Enero 2026 | J130: 08/01/2026 | K130: F E001-00000018 | L130: F E001-00000018 | M130: S/ | N130: -447 | O130: -447 | P130: ADMINISTRACION DE REDES SOCIALES - SEPTIEMBRE - OCTUBRE 2025 + DISEÑO DE BROCHURE CORPORATIVO | Q130: PAGO DE DETRACCION TALLEDO E001-18 | R130: 2026 | S130: 08/01/2026
A131: d | B131: 10410014 BBVA CONTINENTAL ME | C131: 20100130204 | D131: BANCO CONTINENTAL | E131: 03. Pago | F131: 0000002118 | G131: Libro Diario | H131: 46023 | I131: 202601 Enero 2026 | J131: 26/01/2026 | K131: AP 0000000263 | L131: AP 0000000263 | M131: U$ | N131: -123.5 | O131: -414.84 | P131: COMISIONES BBVA DOLARES | Q131: 26/01 COMISIONES BANCARIAS DE ENERO | R131: 2026 | S131: 26/01/2026
A132: d | B132: 10410013 BBVA CONTINENTAL MN | C132: 10097521889 | D132: GOMERO ROJAS, GUILLERMO ALBERTO | E132: 03. Pago | F132: 0000002027 | G132: Libro Diario | H132: 46023 | I132: 202601 Enero 2026 | J132: 20/01/2026 | K132: PR 0000000599 | L132: PR 0000000599 | M132: S/ | N132: -413.51 | O132: -413.51 | P132: PRESTAMO A GG - LUMINARIAS | Q132: 20/01 PRESTAMO A GG - LUMINARIAS | R132: 2026 | S132: 20/01/2026
A133: d | B133: 10410013 BBVA CONTINENTAL MN | C133: 20536612972 | D133: CMO GROUP S.A. | E133: 03. Pago | F133: 0000002066 | G133: Libro Diario | H133: 46023 | I133: 202601 Enero 2026 | J133: 30/01/2026 | K133: PR 0000000596 | L133: PR 0000000596 | M133: S/ | N133: -387.7 | O133: -387.7 | P133: PRESTAMO A CMO POR PAGO A PROVEEDORES - LBS | Q133: 30/01 PRESTAMO A CMO: PAGO A PROVEEDORES | R133: 2026 | S133: 30/01/2026
A134: d | B134: 10410013 BBVA CONTINENTAL MN | C134: 20536612972 | D134: CMO GROUP S.A. | E134: 03. Pago | F134: 0000002069 | G134: Libro Diario | H134: 46023 | I134: 202601 Enero 2026 | J134: 30/01/2026 | K134: PR 0000000596 | L134: PR 0000000596 | M134: S/ | N134: -387.7 | O134: -387.7 | P134: PRESTAMO A CMO POR PAGO A PROVEEDORES - LBS | Q134: 30/01 PRESTAMO A CMO: PAGO A PROVEEDORES | R134: 2026 | S134: 30/01/2026
A135: d | B135: 10410013 BBVA CONTINENTAL MN | C135: 20107167481 | D135: FOTO PLUS S.R.L. | E135: 03. Pago | F135: 0000002050 | G135: Libro Diario | H135: 46023 | I135: 202601 Enero 2026 | J135: 30/01/2026 | K135: AP 0000000262 | L135: AP 0000000262 | M135: S/ | N135: -380 | O135: -380 | P135: ADELANTO A PROVEEDOR SEGUN EECC | Q135: 30/01 PAGO A PROVEEDORES | R135: 2026 | S135: 30/01/2026
...

Sheet Detalle S10_Junio 2026 (3)
A1: Item | B1: Cuenta Contable | C1: RUC Socio de Negocio | D1: Socio de Negocio | E1: Procedencia | F1: N° Asiento | G1: Libro | H1: Mes | I1: Periodo Contable | J1: Fecha de Transacción | K1: N° Documento | L1: N° Documento Pago | M1: MO | N1: Saldo Origen | O1: Saldo ( S/ ) | P1: Observación Documento | Q1: Observación | R1: Año | S1: F.Emisión
A2: b | B2: 10410014 BBVA CONTINENTAL ME | D2: YUPANQUI ARTADI, REYNALDO RICARDO | E2: 02. Transferencia a cuenta bancaria | F2: 0000002098 | G2: Caja y Bancos | H2: 46023 | I2: 202601 Enero 2026 | J2: 26/01/2026 | K2: PR 0000000607 | L2: PR 0000000607 | M2: U$ | N2: 45000 | O2: 151155 | P2: PRESTAMO DE REYNALDO A INTEGRAL | Q2: Transferencia a Cuenta Bancaria | R2: 2026 | S2: 26/01/2026
A3: b | B3: 10410014 BBVA CONTINENTAL ME | D3: YUPANQUI ARTADI, REYNALDO RICARDO | E3: 02. Transferencia a cuenta bancaria | F3: 0000002099 | G3: Caja y Bancos | H3: 46023 | I3: 202601 Enero 2026 | J3: 26/01/2026 | K3: PR 0000000608 | L3: PR 0000000608 | M3: U$ | N3: 45000 | O3: 151155 | P3: PRESTAMO DE REYNALDO A INTEGRAL | Q3: Transferencia a Cuenta Bancaria | R3: 2026 | S3: 26/01/2026
A4: b | B4: 10410013 BBVA CONTINENTAL MN | D4: YUPANQUI ARTADI, REYNALDO RICARDO | E4: 02. Transferencia a cuenta bancaria | F4: 0000002090 | G4: Caja y Bancos | H4: 46023 | I4: 202601 Enero 2026 | J4: 19/01/2026 | K4: PR 0000000589 | L4: PR 0000000589 | M4: S/ | N4: 105000 | O4: 105000 | P4: PRESTAMO DE RY ( ICYS) | Q4: PRESTAMO DE ICYS RY | R4: 2026 | S4: 19/01/2026
A5: b | B5: 10410014 BBVA CONTINENTAL ME | D5: YUPANQUI ARTADI, REYNALDO RICARDO | E5: 02. Transferencia a cuenta bancaria | F5: 0000000609 | G5: Caja y Bancos | H5: 46054 | I5: 202602 Febrero 2026 | J5: 07/02/2026 | K5: PR 0000000639 | L5: PR 0000000639 | M5: U$ | N5: 11850 | O5: 39851.55 | P5: PRESTAMO DE REYNALDO A INTEGRAL | Q5: PRESTAMO DE RY | R5: 2026 | S5: 07/02/2026
A6: b | B6: 10410013 BBVA CONTINENTAL MN | C6: 10415120911 | D6: GUTIERREZ ACQUARONE, GUSTAVO | E6: 02. Transferencia a cuenta bancaria | F6: 0000000605 | G6: Caja y Bancos | H6: 46054 | I6: 202602 Febrero 2026 | J6: 17/02/2026 | K6: DEV 0000000018 | L6: DEV 0000000018 | M6: S/ | N6: 204 | O6: 204 | P6: DEVOLUCION DE ER GG | Q6: DEVOLUCION DE ER | R6: 2026 | S6: 17/02/2026
A7: b | B7: 10410014 BBVA CONTINENTAL ME | E7: 14. Diferencia de cambio - Cuentas | F7: 0000000380 | G7: Diferencia de Cambio | H7: 46054 | I7: 202602 Febrero 2026 | J7: 28/02/2026 | M7: U$ | N7: 0 | O7: 439.12 | P7: Diferencia de cambio - Por Cuenta | Q7: Diferencia de cambio - Por Cuenta | R7: 2026 | S7: 28/02/2026
A8: b | B8: 10410013 BBVA CONTINENTAL MN | C8: 10074121395 | D8: JONES PATRONI, GUILLERMO AUGUSTO | E8: 02. Transferencia a cuenta bancaria | F8: 0000000876 | G8: Caja y Bancos | H8: 46082 | I8: 202603 Marzo 2026 | J8: 13/03/2026 | K8: DEV 0000000019 | L8: DEV 0000000019 | M8: S/ | N8: 3.12 | O8: 3.12 | P8: DEVOLUCION DE ER WILLY JONES | Q8: Transferencia a Cuenta Bancaria | R8: 2026 | S8: 13/03/2026
A9: b | B9: 10410014 BBVA CONTINENTAL ME | C9: 20536612972 | D9: CMO GROUP S.A. | E9: 02. Transferencia a cuenta bancaria | F9: 0000000822 | G9: Caja y Bancos | H9: 46082 | I9: 202603 Marzo 2026 | J9: 04/03/2026 | K9: DP 0000000030 | L9: DP 0000000030 | M9: U$ | N9: 95948 | O9: 326990.78 | P9: INGRESOS DE CMO SEGUN EECC (O.PAGO REC EXT LIQ:9675785) | Q9: INGRESOS CMO | R9: 2026 | S9: 04/03/2026
A10: b | B10: 10410014 BBVA CONTINENTAL ME | E10: 14. Diferencia de cambio - Cuentas | F10: 0000000485 | G10: Diferencia de Cambio | H10: 46082 | I10: 202603 Marzo 2026 | J10: 31/03/2026 | M10: U$ | N10: 0 | O10: 140.3 | P10: Diferencia de cambio - Por Cuenta | Q10: Diferencia de cambio - Por Cuenta | R10: 2026 | S10: 31/03/2026
A11: b | B11: 10410013 BBVA CONTINENTAL MN | C11: 20602384714 | D11: ICYS S.A.C. | E11: 02. Transferencia a cuenta bancaria | F11: 0000003067 | G11: Caja y Bancos | H11: 46113 | I11: 202604 Abril 2026 | J11: 30/04/2026 | K11: PR 0000000694 | L11: PR 0000000694 | M11: S/ | N11: 213000 | O11: 213000 | P11: PRESTAMO RECIBIDO DE ICYS // PARA EL PAGO DE SUNAT IMPUESTO PRICO IGV, PRESTAMO A CMO, ETC | Q11: PRESTAMO RECIBIDO DE ICYS | R11: 2026 | S11: 30/04/2026
A12: b | B12: 10410014 BBVA CONTINENTAL ME | E12: 14. Diferencia de cambio - Cuentas | F12: 0000002966 | G12: Diferencia de Cambio | H12: 46113 | I12: 202604 Abril 2026 | J12: 30/04/2026 | M12: U$ | N12: 0 | O12: 85.26 | P12: Diferencia de cambio - Por Cuenta | Q12: Diferencia de cambio - Por Cuenta | R12: 2026 | S12: 30/04/2026
A13: b | B13: 10410013 BBVA CONTINENTAL MN | D13: YUPANQUI ARTADI, REYNALDO RICARDO | E13: 02. Transferencia a cuenta bancaria | F13: 0000003378 | G13: Caja y Bancos | H13: 46143 | I13: 202605 Mayo 2026 | J13: 29/05/2026 | K13: PR 0000000727 | L13: PR 0000000727 | M13: S/ | N13: 275240 | O13: 275240 | P13: PRESTAMO DE RY | Q13: PRESTAMO RECIBIDO DE RY | R13: 2026 | S13: 29/05/2026
A14: b | B14: 10410013 BBVA CONTINENTAL MN | C14: 20602384714 | D14: ICYS S.A.C. | E14: 02. Transferencia a cuenta bancaria | F14: 0000003417 | G14: Caja y Bancos | H14: 46143 | I14: 202605 Mayo 2026 | J14: 08/05/2026 | K14: PR 0000000728 | L14: PR 0000000728 | M14: S/ | N14: 76100 | O14: 76100 | P14: PRESTAMO RECIBIDO DE ICYS | Q14: PRÉSTAMO DE ICYS | R14: 2026 | S14: 08/05/2026
A15: b | B15: 10410013 BBVA CONTINENTAL MN | C15: 20536612972 | D15: CMO GROUP S.A. | E15: 02. Transferencia a cuenta bancaria | F15: 0000003548 | G15: Caja y Bancos | H15: 46143 | I15: 202605 Mayo 2026 | J15: 13/05/2026 | K15: DP 0000000033 | L15: DP 0000000033 | M15: S/ | N15: 500000 | O15: 500000 | P15: INGRESOS DE CMO - CONSORCIO JULI | Q15: INGRESOS DE CMO - (C - JULY) | R15: 2026 | S15: 13/05/2026
A16: b | B16: 10410013 BBVA CONTINENTAL MN | C16: 20600964608 | D16: SERVICIOS GENERALES DE CONSTRUCCION C & C S.A.C. | E16: 02. Transferencia a cuenta bancaria | F16: 0000003583 | G16: Caja y Bancos | H16: 46143 | I16: 202605 Mayo 2026 | J16: 26/05/2026 | K16: DP 0000000034 | L16: DP 0000000034 | M16: S/ | N16: 48 | O16: 48 | P16: DEVOLUCION POR PAGO EN EXCESO MULTISERVIS E001-292 | Q16: DEVOLUCION DE PAGO EN EXCESO MULTISERVIS | R16: 2026 | S16: 26/05/2026
A17: b | B17: 10410013 BBVA CONTINENTAL MN | C17: 20601402409 | D17: PRODUCTOS Y SERVICIOS SILVA QUEVEDO E.I.R.L. | E17: 02. Transferencia a cuenta bancaria | F17: 0000003419 | G17: Caja y Bancos | H17: 46143 | I17: 202605 Mayo 2026 | J17: 01/05/2026 | K17: DEV 0000000020 | L17: DEV 0000000020 | M17: S/ | N17: 100 | O17: 100 | P17: DEVOLUCION POR GARANNTIA - APERITIVOS DIA DEL TRABAJADOR | Q17: ABONO INMEDIATO 002 JUAN PIO SILVA CAS DEVOLUCIÓN DE LA GARANTÍA (KISU) | R17: 2026 | S17: 01/05/2026
A18: b | B18: 10410013 BBVA CONTINENTAL MN | C18: 10704539237 | D18: CUYUBAMBA SOTO, ARAMIS GABRIEL | E18: 02. Transferencia a cuenta bancaria | F18: 0000003240 | G18: Caja y Bancos | H18: 46143 | I18: 202605 Mayo 2026 | J18: 21/05/2026 | K18: DEV 0000000021 | L18: DEV 0000000021 | M18: S/ | N18: 104.17 | O18: 104.17 | P18: DEVOLUCION DE VIATICOS POR VIAJE A CHOTA DEL 07 AL 08 DE MAYO | Q18: Transferencia a Cuenta Bancaria | R18: 2026 | S18: 21/05/2026
A19: b | B19: 10410013 BBVA CONTINENTAL MN | C19: 20605171941 | D19: CHINA ROAD AND BRIDGE CORPORATION SUCURSAL PERU | E19: 02. Transferencia a cuenta bancaria | F19: 0000003479 | G19: Caja y Bancos | H19: 46143 | I19: 202605 Mayo 2026 | J19: 08/05/2026 | K19: PR 0000000594 | L19: PR 0000000594 | M19: S/ | N19: 2496.88 | O19: 2496.88 | P19: PRESTAMO A CRBC POR VIAJE DE COMISION DE SERVICIOS DE LA OBRA DE CHOTA/ GUILLERMO JONES Y ARAMIS CUYUBAMBA DEL 23 AL 25.02.2026 | Q19: COBRANZA DE PRESTAMO | R19: 2026 | S19: 11/03/2026
A20: b | B20: 10410013 BBVA CONTINENTAL MN | D20: YUPANQUI ARTADI, REYNALDO RICARDO | E20: 02. Transferencia a cuenta bancaria | F20: 0000003859 | G20: Caja y Bancos | H20: 0000000001 | I20: 202606 Junio 2026 | J20: 02/06/2026 | K20: PR 0000000743 | L20: PR 0000000743 | M20: S/ | N20: 51000 | O20: 51000 | P20: PRESTAMO DE RY | Q20: PRESTAMO RECIBIDO PR 743 | R20: 2026 | S20: 02/06/2026
A21: b | B21: 10410013 BBVA CONTINENTAL MN | C21: 20100130204 | D21: BANCO CONTINENTAL | E21: 03. Pago | F21: 0000003925 | G21: Libro Diario | H21: 000000000107 | I21: 202606 Junio 2026 | J21: 09/06/2026 | K21: TR 0000000107 | L21: TR 0000000107 | M21: S/ | N21: -58951.26 | O21: -58951.26 | P21: TRANSFERENCIA DE FONDOS A CUENTA SOLES ADM | Q21: TRANSFERENCIA DE FONDOS A CUENTA SOLES ADM | R21: 2026 | S21: 09/06/2026
A22: b | B22: 10410013 BBVA CONTINENTAL MN | C22: 20536612972 | D22: CMO GROUP S.A. | E22: 02. Transferencia a cuenta bancaria | F22: 0000004005 | G22: Caja y Bancos | H22: 0000000001 | I22: 202606 Junio 2026 | J22: 09/06/2026 | K22: DP 0000000035 | L22: DP 0000000035 | M22: S/ | N22: 59637.25 | O22: 59637.25 | P22: INGRESOS DE CMO | Q22: INGRESOS DE CMO | R22: 2026 | S22: 09/06/2026
A23: b | B23: 10410013 BBVA CONTINENTAL MN | D23: YUPANQUI ARTADI, REYNALDO RICARDO | E23: 02. Transferencia a cuenta bancaria | F23: 0000004012 | G23: Caja y Bancos | H23: 0000000001 | I23: 202606 Junio 2026 | J23: 30/06/2026 | K23: PR 0000000752 | L23: PR 0000000752 | M23: S/ | N23: 182000 | O23: 182000 | P23: PRESTAMO DE RY | Q23: PRESTAMO RECIBIDO RY | R23: 2026 | S23: 30/06/2026
O24: =SUM(O2:O23) -> 2075799.2
K27: RY | O27: 955402
K28: OTROS | O28: -55630
K29: CMO | O29: 886628
K30: ICYS | O30: 289100
O31: =SUBTOTAL(9,O27:O30) -> 2075500

Sheet Hoja2
B3: CMO | C3: -1505086.9
